[2023-08-31 09:31:43] [ERROR] >>>  Main program error:
[2023-08-31 09:31:43] [ERROR] >>>  cannot schedule new futures after interpreter shutdown
[2023-08-31 09:31:43] [ERROR] >>>  Traceback (most recent call last):
  File "C:\Users\allan.yin\PycharmProjects\pythonProject\ah\website\templates\offline_task\data_sync.py", line 392, in execute_sql
    executor.map(process_data_and_insert, [data])
  File "C:\Users\allan.yin\Anaconda3\lib\concurrent\futures\_base.py", line 598, in map
    fs = [self.submit(fn, *args) for args in zip(*iterables)]
  File "C:\Users\allan.yin\Anaconda3\lib\concurrent\futures\_base.py", line 598, in <listcomp>
    fs = [self.submit(fn, *args) for args in zip(*iterables)]
  File "C:\Users\allan.yin\Anaconda3\lib\concurrent\futures\thread.py", line 169, in submit
    raise RuntimeError('cannot schedule new futures after '
RuntimeError: cannot schedule new futures after interpreter shutdown

[2023-08-31 09:31:43] [DEBUG] >>>  Looking for jobs to run
[2023-08-31 09:31:43] [DEBUG] >>>  Next wakeup is due at 2023-08-31 15:45:09.614208+08:00 (in 22405.982853 seconds)
[2023-08-31 09:31:43] [DEBUG] >>>  Looking for jobs to run
[2023-08-31 09:31:43] [DEBUG] >>>  Next wakeup is due at 2023-08-31 15:45:09.614208+08:00 (in 22405.976867 seconds)
[2023-08-31 09:31:43] [DEBUG] >>>  Looking for jobs to run
[2023-08-31 09:31:43] [DEBUG] >>>  Next wakeup is due at 2023-08-31 15:45:09.614208+08:00 (in 22405.971856 seconds)
[2023-08-31 09:31:43] [DEBUG] >>>  Looking for jobs to run
[2023-08-31 09:31:43] [DEBUG] >>>  Next wakeup is due at 2023-08-31 15:45:09.614208+08:00 (in 22405.966852 seconds)
[2023-08-31 09:31:43] [DEBUG] >>>  Looking for jobs to run
[2023-08-31 09:31:43] [INFO] >>>  Job "execute_sql (trigger: cron[hour='9', minute='30', second='0'], next run at: 2023-09-01 09:30:00 CST)" executed successfully
