[2023-09-08 09:44:19] [INFO] >>>  SQLÖ´ÐÐ³É¹¦: func_ods_2156_shangji_detail
[2023-09-08 09:44:19] [ERROR] >>>  Job "execute_sql (trigger: cron[hour='9', minute='30', second='0'], next run at: 2023-09-09 09:30:00 CST)" raised an exception
Traceback (most recent call last):
  File "C:\Users\allan.yin\Anaconda3\lib\site-packages\apscheduler\executors\base.py", line 125, in run_job
    retval = job.func(*job.args, **job.kwargs)
  File "C:\Users\allan.yin\PycharmProjects\pythonProject\ah\website\templates\offline_task\data_sync.py", line 426, in execute_sql
    execute_dependency_jobs(default_engine)
  File "C:\Users\allan.yin\PycharmProjects\pythonProject\ah\website\templates\dags\dags_task.py", line 15, in execute_dependency_jobs
    job_result_all = get_task_result(default_engine, 0)
  File "C:\Users\allan.yin\PycharmProjects\pythonProject\ah\website\templates\data_work\get_task_info.py", line 14, in get_task_result
    username = get_users()
  File "C:\Users\allan.yin\PycharmProjects\pythonProject\ah\website\templates\data_work\get_task_info.py", line 6, in get_users
    if 'username' in session:
  File "C:\Users\allan.yin\Anaconda3\lib\site-packages\werkzeug\local.py", line 316, in __get__
    obj = instance._get_current_object()
  File "C:\Users\allan.yin\Anaconda3\lib\site-packages\werkzeug\local.py", line 513, in _get_current_object
    raise RuntimeError(unbound_message) from None
RuntimeError: Working outside of request context.

This typically means that you attempted to use functionality that needed
an active HTTP request. Consult the documentation on testing for
information about how to avoid this problem.
